<?xml version="1.0" encoding="UTF-8"?><testrun name="UserDAOTestCase" project="ShoppingCartBackEnd" tests="1" started="1" failures="0" errors="1" ignored="0">
  <testsuite name="com.niit.shoppingcart.UserDAOTestCase" time="2.04">
    <testcase name="createUserTestCase" classname="com.niit.shoppingcart.UserDAOTestCase" time="2.04">
      <error>org.springframework.transaction.CannotCreateTransactionException: Could not open Hibernate Session for transaction; nested exception is org.hibernate.exception.GenericJDBCException: Could not open connection&#13;
	at org.springframework.orm.hibernate4.HibernateTransactionManager.doBegin(HibernateTransactionManager.java:544)&#13;
	at org.springframework.transaction.support.AbstractPlatformTransactionManager.getTransaction(AbstractPlatformTransactionManager.java:373)&#13;
	at org.springframework.transaction.interceptor.TransactionAspectSupport.createTransactionIfNecessary(TransactionAspectSupport.java:430)&#13;
	at org.springframework.transaction.interceptor.TransactionAspectSupport.invokeWithinTransaction(TransactionAspectSupport.java:276)&#13;
	at org.springframework.transaction.interceptor.TransactionInterceptor.invoke(TransactionInterceptor.java:96)&#13;
	at org.springframework.aop.framework.ReflectiveMethodInvocation.proceed(ReflectiveMethodInvocation.java:179)&#13;
	at org.springframework.aop.framework.JdkDynamicAopProxy.invoke(JdkDynamicAopProxy.java:213)&#13;
	at com.sun.proxy.$Proxy28.save(Unknown Source)&#13;
	at com.niit.shoppingcart.UserDAOTestCase.createUserTestCase(UserDAOTestCase.java:52)&#13;
	at sun.reflect.NativeMethodAccessorImpl.invoke0(Native Method)&#13;
	at sun.reflect.NativeMethodAccessorImpl.invoke(NativeMethodAccessorImpl.java:62)&#13;
	at sun.reflect.DelegatingMethodAccessorImpl.invoke(DelegatingMethodAccessorImpl.java:43)&#13;
	at java.lang.reflect.Method.invoke(Method.java:498)&#13;
	at org.junit.runners.model.FrameworkMethod$1.runReflectiveCall(FrameworkMethod.java:50)&#13;
	at org.junit.internal.runners.model.ReflectiveCallable.run(ReflectiveCallable.java:12)&#13;
	at org.junit.runners.model.FrameworkMethod.invokeExplosively(FrameworkMethod.java:47)&#13;
	at org.junit.internal.runners.statements.InvokeMethod.evaluate(InvokeMethod.java:17)&#13;
	at org.junit.runners.ParentRunner.runLeaf(ParentRunner.java:325)&#13;
	at org.junit.runners.BlockJUnit4ClassRunner.runChild(BlockJUnit4ClassRunner.java:78)&#13;
	at org.junit.runners.BlockJUnit4ClassRunner.runChild(BlockJUnit4ClassRunner.java:57)&#13;
	at org.junit.runners.ParentRunner$3.run(ParentRunner.java:290)&#13;
	at org.junit.runners.ParentRunner$1.schedule(ParentRunner.java:71)&#13;
	at org.junit.runners.ParentRunner.runChildren(ParentRunner.java:288)&#13;
	at org.junit.runners.ParentRunner.access$000(ParentRunner.java:58)&#13;
	at org.junit.runners.ParentRunner$2.evaluate(ParentRunner.java:268)&#13;
	at org.junit.internal.runners.statements.RunBefores.evaluate(RunBefores.java:26)&#13;
	at org.junit.runners.ParentRunner.run(ParentRunner.java:363)&#13;
	at org.eclipse.jdt.internal.junit4.runner.JUnit4TestReference.run(JUnit4TestReference.java:86)&#13;
	at org.eclipse.jdt.internal.junit.runner.TestExecution.run(TestExecution.java:38)&#13;
	at org.eclipse.jdt.internal.junit.runner.RemoteTestRunner.runTests(RemoteTestRunner.java:459)&#13;
	at org.eclipse.jdt.internal.junit.runner.RemoteTestRunner.runTests(RemoteTestRunner.java:678)&#13;
	at org.eclipse.jdt.internal.junit.runner.RemoteTestRunner.run(RemoteTestRunner.java:382)&#13;
	at org.eclipse.jdt.internal.junit.runner.RemoteTestRunner.main(RemoteTestRunner.java:192)&#13;
Caused by: org.hibernate.exception.GenericJDBCException: Could not open connection&#13;
	at org.hibernate.exception.internal.StandardSQLExceptionConverter.convert(StandardSQLExceptionConverter.java:54)&#13;
	at org.hibernate.engine.jdbc.spi.SqlExceptionHelper.convert(SqlExceptionHelper.java:126)&#13;
	at org.hibernate.engine.jdbc.spi.SqlExceptionHelper.convert(SqlExceptionHelper.java:112)&#13;
	at org.hibernate.engine.jdbc.internal.LogicalConnectionImpl.obtainConnection(LogicalConnectionImpl.java:235)&#13;
	at org.hibernate.engine.jdbc.internal.LogicalConnectionImpl.getConnection(LogicalConnectionImpl.java:171)&#13;
	at org.hibernate.internal.SessionImpl.connection(SessionImpl.java:450)&#13;
	at org.springframework.orm.hibernate4.HibernateTransactionManager.doBegin(HibernateTransactionManager.java:450)&#13;
	... 32 more&#13;
Caused by: org.h2.jdbc.JdbcSQLException: Connection is broken: "java.net.ConnectException: Connection refused: connect: localhost" [90067-194]&#13;
	at org.h2.message.DbException.getJdbcSQLException(DbException.java:345)&#13;
	at org.h2.message.DbException.get(DbException.java:168)&#13;
	at org.h2.engine.SessionRemote.connectServer(SessionRemote.java:457)&#13;
	at org.h2.engine.SessionRemote.connectEmbeddedOrServer(SessionRemote.java:334)&#13;
	at org.h2.jdbc.JdbcConnection.&lt;init&gt;(JdbcConnection.java:116)&#13;
	at org.h2.jdbc.JdbcConnection.&lt;init&gt;(JdbcConnection.java:100)&#13;
	at org.h2.Driver.connect(Driver.java:69)&#13;
	at java.sql.DriverManager.getConnection(DriverManager.java:664)&#13;
	at java.sql.DriverManager.getConnection(DriverManager.java:208)&#13;
	at org.springframework.jdbc.datasource.DriverManagerDataSource.getConnectionFromDriverManager(DriverManagerDataSource.java:153)&#13;
	at org.springframework.jdbc.datasource.DriverManagerDataSource.getConnectionFromDriver(DriverManagerDataSource.java:144)&#13;
	at org.springframework.jdbc.datasource.AbstractDriverBasedDataSource.getConnectionFromDriver(AbstractDriverBasedDataSource.java:196)&#13;
	at org.springframework.jdbc.datasource.AbstractDriverBasedDataSource.getConnection(AbstractDriverBasedDataSource.java:159)&#13;
	at org.hibernate.engine.jdbc.connections.internal.DatasourceConnectionProviderImpl.getConnection(DatasourceConnectionProviderImpl.java:139)&#13;
	at org.hibernate.internal.AbstractSessionImpl$NonContextualJdbcConnectionAccess.obtainConnection(AbstractSessionImpl.java:380)&#13;
	at org.hibernate.engine.jdbc.internal.LogicalConnectionImpl.obtainConnection(LogicalConnectionImpl.java:228)&#13;
	... 35 more&#13;
Caused by: java.net.ConnectException: Connection refused: connect&#13;
	at java.net.DualStackPlainSocketImpl.waitForConnect(Native Method)&#13;
	at java.net.DualStackPlainSocketImpl.socketConnect(DualStackPlainSocketImpl.java:85)&#13;
	at java.net.AbstractPlainSocketImpl.doConnect(AbstractPlainSocketImpl.java:350)&#13;
	at java.net.AbstractPlainSocketImpl.connectToAddress(AbstractPlainSocketImpl.java:206)&#13;
	at java.net.AbstractPlainSocketImpl.connect(AbstractPlainSocketImpl.java:188)&#13;
	at java.net.PlainSocketImpl.connect(PlainSocketImpl.java:172)&#13;
	at java.net.SocksSocketImpl.connect(SocksSocketImpl.java:392)&#13;
	at java.net.Socket.connect(Socket.java:589)&#13;
	at org.h2.util.NetUtils.createSocket(NetUtils.java:123)&#13;
	at org.h2.util.NetUtils.createSocket(NetUtils.java:103)&#13;
	at org.h2.engine.SessionRemote.initTransfer(SessionRemote.java:115)&#13;
	at org.h2.engine.SessionRemote.connectServer(SessionRemote.java:453)&#13;
	... 48 more&#13;
&#13;
</error>
    </testcase>
  </testsuite>
</testrun>
